Workbook

Sheet How to use
A1: Household Finances - how to use
A2: Couples' budget, spending and savings tracker
B4: Colour key
B5: Yellow cells | C5: Type here - these are your inputs.
B6: Grey cells | C6: Calculated automatically - don't type over them.
B7: Blue text / green text | C7: Blue = something you entered, green = pulled from another tab.
B9: 1. Settings | C9: Put in both names, your accounts (each one owned by you, your partner or Joint), your categories and a monthly budget for each. Mark each expense Essential Yes/No.
B10: 2. Regular Bills | C10: List everything that repeats - salaries, rent, bills, subscriptions. Shows your committed monthly/yearly cost and flags things worth reviewing.
B11: 3. Transactions | C11: Log each incoming/outgoing as it happens (or paste from a bank export). Pick account, type and category from the drop-downs; amounts are positive.
C12: Moving money between your own accounts (e.g. your pot into Joint)? Use Type = Transfer and fill 'To account' - it won't be counted as spending.
B13: 4. Savings / Savings Log | C13: Set goals with targets and dates; log every deposit. See % done and how much you need to put away each month.
B14: 5. Dashboard | C14: Pick a month. See income, spending, savings and what's left over for each of you, Joint and the household - plus every category against its budget.
B15: 6. Where to Save | C15: Your biggest discretionary categories, where you're over budget, the yearly cost of subscriptions and what a % cut would save over a year.
B17: Example data | C17: Rows marked 'Example - delete' show the format. Clear the yellow cells on Transactions, Regular Bills, Savings and Savings Log when you start for real (don't delete whole rows - just clear the contents).
B18: Room | C18: Transactions: 2000 rows, Savings Log: 1000, Regular Bills: 60. Start a new copy each year.

Sheet Dashboard
A1: Monthly dashboard
A2: Change the month in the yellow cell. Everything below recalculates from Transactions, Savings Log and Regular Bills.
B3: Month to show | C3: 46296 | D3: =DATE(YEAR(C3),MONTH(C3),1) -> 46296
B5: Who earned, spent and saved
C6: =Settings!C3 -> Me | D6: =Settings!C4 -> Partner | E6: Joint | F6: Household
B7: Income | C7: =SUMIFS(Transactions!$F$5:$F$2004,Transactions!$I$5:$I$2004,C$6,Transactions!$D$5:$D$2004,"Income",Transactions!$K$5:$K$2004,$D$3) -> 2650 | D7: =SUMIFS(Transactions!$F$5:$F$2004,Transactions!$I$5:$I$2004,D$6,Transactions!$D$5:$D$2004,"Income",Transactions!$K$5:$K$2004,$D$3) -> 2400 | E7: =SUMIFS(Transactions!$F$5:$F$2004,Transactions!$I$5:$I$2004,E$6,Transactions!$D$5:$D$2004,"Income",Transactions!$K$5:$K$2004,$D$3) -> 0 | F7: =SUM(C7:E7) -> 5050
B8: Spending | C8: =SUMIFS(Transactions!$F$5:$F$2004,Transactions!$I$5:$I$2004,C$6,Transactions!$D$5:$D$2004,"Expense",Transactions!$K$5:$K$2004,$D$3) -> 99.49 | D8: =SUMIFS(Transactions!$F$5:$F$2004,Transactions!$I$5:$I$2004,D$6,Transactions!$D$5:$D$2004,"Expense",Transactions!$K$5:$K$2004,$D$3) -> 139.2 | E8: =SUMIFS(Transactions!$F$5:$F$2004,Transactions!$I$5:$I$2004,E$6,Transactions!$D$5:$D$2004,"Expense",Transactions!$K$5:$K$2004,$D$3) -> 1318.45 | F8: =SUM(C8:E8) -> 1557.14
B9: Transfers in | C9: =SUMIFS(Transactions!$F$5:$F$2004,Transactions!$J$5:$J$2004,C$6,Transactions!$D$5:$D$2004,"Transfer",Transactions!$K$5:$K$2004,$D$3) -> 0 | D9: =SUMIFS(Transactions!$F$5:$F$2004,Transactions!$J$5:$J$2004,D$6,Transactions!$D$5:$D$2004,"Transfer",Transactions!$K$5:$K$2004,$D$3) -> 0 | E9: =SUMIFS(Transactions!$F$5:$F$2004,Transactions!$J$5:$J$2004,E$6,Transactions!$D$5:$D$2004,"Transfer",Transactions!$K$5:$K$2004,$D$3) -> 2100 | F9: =SUM(C9:E9) -> 2100
B10: Transfers out | C10: =SUMIFS(Transactions!$F$5:$F$2004,Transactions!$I$5:$I$2004,C$6,Transactions!$D$5:$D$2004,"Transfer",Transactions!$K$5:$K$2004,$D$3) -> 1100 | D10: =SUMIFS(Transactions!$F$5:$F$2004,Transactions!$I$5:$I$2004,D$6,Transactions!$D$5:$D$2004,"Transfer",Transactions!$K$5:$K$2004,$D$3) -> 1000 | E10: =SUMIFS(Transactions!$F$5:$F$2004,Transactions!$I$5:$I$2004,E$6,Transactions!$D$5:$D$2004,"Transfer",Transactions!$K$5:$K$2004,$D$3) -> 0 | F10: =SUM(C10:E10) -> 2100
B11: Saved | C11: =SUMIFS('Savings Log'!$D$5:$D$1004,'Savings Log'!$F$5:$F$1004,C$6,'Savings Log'!$G$5:$G$1004,$D$3) -> 350 | D11: =SUMIFS('Savings Log'!$D$5:$D$1004,'Savings Log'!$F$5:$F$1004,D$6,'Savings Log'!$G$5:$G$1004,$D$3) -> 150 | E11: =SUMIFS('Savings Log'!$D$5:$D$1004,'Savings Log'!$F$5:$F$1004,E$6,'Savings Log'!$G$5:$G$1004,$D$3) -> 0 | F11: =SUM(C11:E11) -> 500
B12: Left over | C12: =C7-C8+C9-C10-C11 -> 1100.51 | D12: =D7-D8+D9-D10-D11 -> 1110.8 | E12: =E7-E8+E9-E10-E11 -> 781.55 | F12: =SUM(C12:E12) -> 2992.86
B13: Savings rate | C13: =IF(C7>0,C11/C7,"") -> 0.13207547 | D13: =IF(D7>0,D11/D7,"") -> 0.0625 | E13: =IF(E7>0,E11/E7,"") | F13: =IF(F7>0,F11/F7,"") -> 0.099009901
B14: Regular bills (planned / month) | C14: =SUMIFS('Regular Bills'!$G$5:$G$64,'Regular Bills'!$I$5:$I$64,C$6,'Regular Bills'!$C$5:$C$64,"Expense") -> 20.906667 | D14: =SUMIFS('Regular Bills'!$G$5:$G$64,'Regular Bills'!$I$5:$I$64,D$6,'Regular Bills'!$C$5:$C$64,"Expense") -> 40.083333 | E14: =SUMIFS('Regular Bills'!$G$5:$G$64,'Regular Bills'!$I$5:$I$64,E$6,'Regular Bills'!$C$5:$C$64,"Expense") -> 1580 | F14: =SUM(C14:E14) -> 1640.99
B15: Transfers = money moved between your own accounts (e.g. into Joint); they cancel out in the Household column. Left over = income - spending + transfers in - out - saved.
B17: Spending by category vs budget
B18: Category | C18: Budget | D18: =Settings!C3 -> Me | E18: =Settings!C4 -> Partner | F18: Joint | G18: Total spent | H18: Left in budget | I18: % of budget used | J18: 3-month average
B19: =IF(Settings!H14="","",Settings!H14) -> Rent / Mortgage | C19: =IF(B19="","",N(Settings!J14)) -> 1200 | D19: =IF($B19="","",SUMIFS(Transactions!$F$5:$F$2004,Transactions!$E$5:$E$2004,$B19,Transactions!$D$5:$D$2004,"Expense",Transactions!$I$5:$I$2004,D$18,Transactions!$K$5:$K$2004,$D$3)) -> 0 | E19: =IF($B19="","",SUMIFS(Transactions!$F$5:$F$2004,Transactions!$E$5:$E$2004,$B19,Transactions!$D$5:$D$2004,"Expense",Transactions!$I$5:$I$2004,E$18,Transactions!$K$5:$K$2004,$D$3)) -> 0 | F19: =IF($B19="","",SUMIFS(Transactions!$F$5:$F$2004,Transactions!$E$5:$E$2004,$B19,Transactions!$D$5:$D$2004,"Expense",Transactions!$I$5:$I$2004,F$18,Transactions!$K$5:$K$2004,$D$3)) -> 1200 | G19: =IF(B19="","",SUM(D19:F19)) -> 1200 | H19: =IF(B19="","",C19-G19) -> 0 | I19: =IF(OR(B19="",N(C19)=0),"",G19/C19) -> 1 | J19: =IF(B19="","",SUMIFS(Transactions!$F$5:$F$2004,Transactions!$E$5:$E$2004,$B19,Transactions!$D$5:$D$2004,"Expense",Transactions!$K$5:$K$2004,">="&EDATE($D$3,-2),Transactions!$K$5:$K$2004,"<="&$D$3)/3) -> 800
B20: =IF(Settings!H15="","",Settings!H15) -> Council Tax | C20: =IF(B20="","",N(Settings!J15)) -> 160 | D20: =IF($B20="","",SUMIFS(Transactions!$F$5:$F$2004,Transactions!$E$5:$E$2004,$B20,Transactions!$D$5:$D$2004,"Expense",Transactions!$I$5:$I$2004,D$18,Transactions!$K$5:$K$2004,$D$3)) -> 0 | E20: =IF($B20="","",SUMIFS(Transactions!$F$5:$F$2004,Transactions!$E$5:$E$2004,$B20,Transactions!$D$5:$D$2004,"Expense",Transactions!$I$5:$I$2004,E$18,Transactions!$K$5:$K$2004,$D$3)) -> 0 | F20: =IF($B20="","",SUMIFS(Transactions!$F$5:$F$2004,Transactions!$E$5:$E$2004,$B20,Transactions!$D$5:$D$2004,"Expense",Transactions!$I$5:$I$2004,F$18,Transactions!$K$5:$K$2004,$D$3)) -> 0 | G20: =IF(B20="","",SUM(D20:F20)) -> 0 | H20: =IF(B20="","",C20-G20) -> 160 | I20: =IF(OR(B20="",N(C20)=0),"",G20/C20) -> 0 | J20: =IF(B20="","",SUMIFS(Transactions!$F$5:$F$2004,Transactions!$E$5:$E$2004,$B20,Transactions!$D$5:$D$2004,"Expense",Transactions!$K$5:$K$2004,">="&EDATE($D$3,-2),Transactions!$K$5:$K$2004,"<="&$D$3)/3) -> 0
B21: =IF(Settings!H16="","",Settings!H16) -> Energy | C21: =IF(B21="","",N(Settings!J16)) -> 140 | D21: =IF($B21="","",SUMIFS(Transactions!$F$5:$F$2004,Transactions!$E$5:$E$2004,$B21,Transactions!$D$5:$D$2004,"Expense",Transactions!$I$5:$I$2004,D$18,Transactions!$K$5:$K$2004,$D$3)) -> 0 | E21: =IF($B21="","",SUMIFS(Transactions!$F$5:$F$2004,Transactions!$E$5:$E$2004,$B21,Transactions!$D$5:$D$2004,"Expense",Transactions!$I$5:$I$2004,E$18,Transactions!$K$5:$K$2004,$D$3)) -> 0 | F21: =IF($B21="","",SUMIFS(Transactions!$F$5:$F$2004,Transactions!$E$5:$E$2004,$B21,Transactions!$D$5:$D$2004,"Expense",Transactions!$I$5:$I$2004,F$18,Transactions!$K$5:$K$2004,$D$3)) -> 0 | G21: =IF(B21="","",SUM(D21:F21)) -> 0 | H21: =IF(B21="","",C21-G21) -> 140 | I21: =IF(OR(B21="",N(C21)=0),"",G21/C21) -> 0 | J21: =IF(B21="","",SUMIFS(Transactions!$F$5:$F$2004,Transactions!$E$5:$E$2004,$B21,Transactions!$D$5:$D$2004,"Expense",Transactions!$K$5:$K$2004,">="&EDATE($D$3,-2),Transactions!$K$5:$K$2004,"<="&$D$3)/3) -> 0
B22: =IF(Settings!H17="","",Settings!H17) -> Water | C22: =IF(B22="","",N(Settings!J17)) -> 40 | D22: =IF($B22="","",SUMIFS(Transactions!$F$5:$F$2004,Transactions!$E$5:$E$2004,$B22,Transactions!$D$5:$D$2004,"Expense",Transactions!$I$5:$I$2004,D$18,Transactions!$K$5:$K$2004,$D$3)) -> 0 | E22: =IF($B22="","",SUMIFS(Transactions!$F$5:$F$2004,Transactions!$E$5:$E$2004,$B22,Transactions!$D$5:$D$2004,"Expense",Transactions!$I$5:$I$2004,E$18,Transactions!$K$5:$K$2004,$D$3)) -> 0 | F22: =IF($B22="","",SUMIFS(Transactions!$F$5:$F$2004,Transactions!$E$5:$E$2004,$B22,Transactions!$D$5:$D$2004,"Expense",Transactions!$I$5:$I$2004,F$18,Transactions!$K$5:$K$2004,$D$3)) -> 0 | G22: =IF(B22="","",SUM(D22:F22)) -> 0 | H22: =IF(B22="","",C22-G22) -> 40 | I22: =IF(OR(B22="",N(C22)=0),"",G22/C22) -> 0 | J22: =IF(B22="","",SUMIFS(Transactions!$F$5:$F$2004,Transactions!$E$5:$E$2004,$B22,Transactions!$D$5:$D$2004,"Expense",Transactions!$K$5:$K$2004,">="&EDATE($D$3,-2),Transactions!$K$5:$K$2004,"<="&$D$3)/3) -> 0
B23: =IF(Settings!H18="","",Settings!H18) -> Broadband & Phone | C23: =IF(B23="","",N(Settings!J18)) -> 70 | D23: =IF($B23="","",SUMIFS(Transactions!$F$5:$F$2004,Transactions!$E$5:$E$2004,$B23,Transactions!$D$5:$D$2004,"Expense",Transactions!$I$5:$I$2004,D$18,Transactions!$K$5:$K$2004,$D$3)) -> 0 | E23: =IF($B23="","",SUMIFS(Transactions!$F$5:$F$2004,Transactions!$E$5:$E$2004,$B23,Transactions!$D$5:$D$2004,"Expense",Transactions!$I$5:$I$2004,E$18,Transactions!$K$5:$K$2004,$D$3)) -> 0 | F23: =IF($B23="","",SUMIFS(Transactions!$F$5:$F$2004,Transactions!$E$5:$E$2004,$B23,Transactions!$D$5:$D$2004,"Expense",Transactions!$I$5:$I$2004,F$18,Transactions!$K$5:$K$2004,$D$3)) -> 0 | G23: =IF(B23="","",SUM(D23:F23)) -> 0 | H23: =IF(B23="","",C23-G23) -> 70 | I23: =IF(OR(B23="",N(C23)=0),"",G23/C23) -> 0 | J23: =IF(B23="","",SUMIFS(Transactions!$F$5:$F$2004,Transactions!$E$5:$E$2004,$B23,Transactions!$D$5:$D$2004,"Expense",Transactions!$K$5:$K$2004,">="&EDATE($D$3,-2),Transactions!$K$5:$K$2004,"<="&$D$3)/3) -> 0
B24: =IF(Settings!H19="","",Settings!H19) -> Insurance | C24: =IF(B24="","",N(Settings!J19)) -> 60 | D24: =IF($B24="","",SUMIFS(Transactions!$F$5:$F$2004,Transactions!$E$5:$E$2004,$B24,Transactions!$D$5:$D$2004,"Expense",Transactions!$I$5:$I$2004,D$18,Transactions!$K$5:$K$2004,$D$3)) -> 0 | E24: =IF($B24="","",SUMIFS(Transactions!$F$5:$F$2004,Transactions!$E$5:$E$2004,$B24,Transactions!$D$5:$D$2004,"Expense",Transactions!$I$5:$I$2004,E$18,Transactions!$K$5:$K$2004,$D$3)) -> 0 | F24: =IF($B24="","",SUMIFS(Transactions!$F$5:$F$2004,Transactions!$E$5:$E$2004,$B24,Transactions!$D$5:$D$2004,"Expense",Transactions!$I$5:$I$2004,F$18,Transactions!$K$5:$K$2004,$D$3)) -> 0 | G24: =IF(B24="","",SUM(D24:F24)) -> 0 | H24: =IF(B24="","",C24-G24) -> 60 | I24: =IF(OR(B24="",N(C24)=0),"",G24/C24) -> 0 | J24: =IF(B24="","",SUMIFS(Transactions!$F$5:$F$2004,Transactions!$E$5:$E$2004,$B24,Transactions!$D$5:$D$2004,"Expense",Transactions!$K$5:$K$2004,">="&EDATE($D$3,-2),Transactions!$K$5:$K$2004,"<="&$D$3)/3) -> 0
B25: =IF(Settings!H20="","",Settings!H20) -> Groceries | C25: =IF(B25="","",N(Settings!J20)) -> 450 | D25: =IF($B25="","",SUMIFS(Transactions!$F$5:$F$2004,Transactions!$E$5:$E$2004,$B25,Transactions!$D$5:$D$2004,"Expense",Transactions!$I$5:$I$2004,D$18,Transactions!$K$5:$K$2004,$D$3)) -> 0 | E25: =IF($B25="","",SUMIFS(Transactions!$F$5:$F$2004,Transactions!$E$5:$E$2004,$B25,Transactions!$D$5:$D$2004,"Expense",Transactions!$I$5:$I$2004,E$18,Transactions!$K$5:$K$2004,$D$3)) -> 0 | F25: =IF($B25="","",SUMIFS(Transactions!$F$5:$F$2004,Transactions!$E$5:$E$2004,$B25,Transactions!$D$5:$D$2004,"Expense",Transactions!$I$5:$I$2004,F$18,Transactions!$K$5:$K$2004,$D$3)) -> 118.45 | G25: =IF(B25="","",SUM(D25:F25)) -> 118.45 | H25: =IF(B25="","",C25-G25) -> 331.55 | I25: =IF(OR(B25="",N(C25)=0),"",G25/C25) -> 0.26322222 | J25: =IF(B25="","",SUMIFS(Transactions!$F$5:$F$2004,Transactions!$E$5:$E$2004,$B25,Transactions!$D$5:$D$2004,"Expense",Transactions!$K$5:$K$2004,">="&EDATE($D$3,-2),Transactions!$K$5:$K$2004,"<="&$D$3)/3) -> 196.15
B26: =IF(Settings!H21="","",Settings!H21) -> Transport & Fuel | C26: =IF(B26="","",N(Settings!J21)) -> 180 | D26: =IF($B26="","",SUMIFS(Transactions!$F$5:$F$2004,Transactions!$E$5:$E$2004,$B26,Transactions!$D$5:$D$2004,"Expense",Transactions!$I$5:$I$2004,D$18,Transactions!$K$5:$K$2004,$D$3)) -> 0 | E26: =IF($B26="","",SUMIFS(Transactions!$F$5:$F$2004,Transactions!$E$5:$E$2004,$B26,Transactions!$D$5:$D$2004,"Expense",Transactions!$I$5:$I$2004,E$18,Transactions!$K$5:$K$2004,$D$3)) -> 64.2 | F26: =IF($B26="","",SUMIFS(Transactions!$F$5:$F$2004,Transactions!$E$5:$E$2004,$B26,Transactions!$D$5:$D$2004,"Expense",Transactions!$I$5:$I$2004,F$18,Transactions!$K$5:$K$2004,$D$3)) -> 0 | G26: =IF(B26="","",SUM(D26:F26)) -> 64.2 | H26: =IF(B26="","",C26-G26) -> 115.8 | I26: =IF(OR(B26="",N(C26)=0),"",G26/C26) -> 0.35666667 | J26: =IF(B26="","",SUMIFS(Transactions!$F$5:$F$2004,Transactions!$E$5:$E$2004,$B26,Transactions!$D$5:$D$2004,"Expense",Transactions!$K$5:$K$2004,">="&EDATE($D$3,-2),Transactions!$K$5:$K$2004,"<="&$D$3)/3) -> 21.4
B27: =IF(Settings!H22="","",Settings!H22) -> Health | C27: =IF(B27="","",N(Settings!J22)) -> 30 | D27: =IF($B27="","",SUMIFS(Transactions!$F$5:$F$2004,Transactions!$E$5:$E$2004,$B27,Transactions!$D$5:$D$2004,"Expense",Transactions!$I$5:$I$2004,D$18,Transactions!$K$5:$K$2004,$D$3)) -> 0 | E27: =IF($B27="","",SUMIFS(Transactions!$F$5:$F$2004,Transactions!$E$5:$E$2004,$B27,Transactions!$D$5:$D$2004,"Expense",Transactions!$I$5:$I$2004,E$18,Transactions!$K$5:$K$2004,$D$3)) -> 0 | F27: =IF($B27="","",SUMIFS(Transactions!$F$5:$F$2004,Transactions!$E$5:$E$2004,$B27,Transactions!$D$5:$D$2004,"Expense",Transactions!$I$5:$I$2004,F$18,Transactions!$K$5:$K$2004,$D$3)) -> 0 | G27: =IF(B27="","",SUM(D27:F27)) -> 0 | H27: =IF(B27="","",C27-G27) -> 30 | I27: =IF(OR(B27="",N(C27)=0),"",G27/C27) -> 0 | J27: =IF(B27="","",SUMIFS(Transactions!$F$5:$F$2004,Transactions!$E$5:$E$2004,$B27,Transactions!$D$5:$D$2004,"Expense",Transactions!$K$5:$K$2004,">="&EDATE($D$3,-2),Transactions!$K$5:$K$2004,"<="&$D$3)/3) -> 0
B28: =IF(Settings!H23="","",Settings!H23) -> Childcare & Kids | C28: =IF(B28="","",N(Settings!J23)) -> 0 | D28: =IF($B28="","",SUMIFS(Transactions!$F$5:$F$2004,Transactions!$E$5:$E$2004,$B28,Transactions!$D$5:$D$2004,"Expense",Transactions!$I$5:$I$2004,D$18,Transactions!$K$5:$K$2004,$D$3)) -> 0 | E28: =IF($B28="","",SUMIFS(Transactions!$F$5:$F$2004,Transactions!$E$5:$E$2004,$B28,Transactions!$D$5:$D$2004,"Expense",Transactions!$I$5:$I$2004,E$18,Transactions!$K$5:$K$2004,$D$3)) -> 0 | F28: =IF($B28="","",SUMIFS(Transactions!$F$5:$F$2004,Transactions!$E$5:$E$2004,$B28,Transactions!$D$5:$D$2004,"Expense",Transactions!$I$5:$I$2004,F$18,Transactions!$K$5:$K$2004,$D$3)) -> 0 | G28: =IF(B28="","",SUM(D28:F28)) -> 0 | H28: =IF(B28="","",C28-G28) -> 0 | I28: =IF(OR(B28="",N(C28)=0),"",G28/C28) | J28: =IF(B28="","",SUMIFS(Transactions!$F$5:$F$2004,Transactions!$E$5:$E$2004,$B28,Transactions!$D$5:$D$2004,"Expense",Transactions!$K$5:$K$2004,">="&EDATE($D$3,-2),Transactions!$K$5:$K$2004,"<="&$D$3)/3) -> 0
B29: =IF(Settings!H24="","",Settings!H24) -> Debt Repayments | C29: =IF(B29="","",N(Settings!J24)) -> 0 | D29: =IF($B29="","",SUMIFS(Transactions!$F$5:$F$2004,Transactions!$E$5:$E$2004,$B29,Transactions!$D$5:$D$2004,"Expense",Transactions!$I$5:$I$2004,D$18,Transactions!$K$5:$K$2004,$D$3)) -> 0 | E29: =IF($B29="","",SUMIFS(Transactions!$F$5:$F$2004,Transactions!$E$5:$E$2004,$B29,Transactions!$D$5:$D$2004,"Expense",Transactions!$I$5:$I$2004,E$18,Transactions!$K$5:$K$2004,$D$3)) -> 0 | F29: =IF($B29="","",SUMIFS(Transactions!$F$5:$F$2004,Transactions!$E$5:$E$2004,$B29,Transactions!$D$5:$D$2004,"Expense",Transactions!$I$5:$I$2004,F$18,Transactions!$K$5:$K$2004,$D$3)) -> 0 | G29: =IF(B29="","",SUM(D29:F29)) -> 0 | H29: =IF(B29="","",C29-G29) -> 0 | I29: =IF(OR(B29="",N(C29)=0),"",G29/C29) | J29: =IF(B29="","",SUMIFS(Transactions!$F$5:$F$2004,Transactions!$E$5:$E$2004,$B29,Transactions!$D$5:$D$2004,"Expense",Transactions!$K$5:$K$2004,">="&EDATE($D$3,-2),Transactions!$K$5:$K$2004,"<="&$D$3)/3) -> 0
B30: =IF(Settings!H25="","",Settings!H25) -> Eating Out | C30: =IF(B30="","",N(Settings!J25)) -> 150 | D30: =IF($B30="","",SUMIFS(Transactions!$F$5:$F$2004,Transactions!$E$5:$E$2004,$B30,Transactions!$D$5:$D$2004,"Expense",Transactions!$I$5:$I$2004,D$18,Transactions!$K$5:$K$2004,$D$3)) -> 86.5 | E30: =IF($B30="","",SUMIFS(Transactions!$F$5:$F$2004,Transactions!$E$5:$E$2004,$B30,Transactions!$D$5:$D$2004,"Expense",Transactions!$I$5:$I$2004,E$18,Transactions!$K$5:$K$2004,$D$3)) -> 0 | F30: =IF($B30="","",SUMIFS(Transactions!$F$5:$F$2004,Transactions!$E$5:$E$2004,$B30,Transactions!$D$5:$D$2004,"Expense",Transactions!$I$5:$I$2004,F$18,Transactions!$K$5:$K$2004,$D$3)) -> 0 | G30: =IF(B30="","",SUM(D30:F30)) -> 86.5 | H30: =IF(B30="","",C30-G30) -> 63.5 | I30: =IF(OR(B30="",N(C30)=0),"",G30/C30) -> 0.57666667 | J30: =IF(B30="","",SUMIFS(Transactions!$F$5:$F$2004,Transactions!$E$5:$E$2004,$B30,Transactions!$D$5:$D$2004,"Expense",Transactions!$K$5:$K$2004,">="&EDATE($D$3,-2),Transactions!$K$5:$K$2004,"<="&$D$3)/3) -> 98.833333
... B43: =IF(Settings!H38="","",Settings!H38) | C43: =IF(B43="","",N(Settings!J38)) | D43: =IF($B43="","",SUMIFS(Transactions!$F$5:$F$2004,Transactions!$E$5:$E$2004,$B43,Transactions!$D$5:$D$2004,"Expense",Transactions!$I$5:$I$2004,D$18,Transactions!$K$5:$K$2004,$D$3)) | E43: =IF($B43="","",SUMIFS(Transactions!$F$5:$F$2004,Transactions!$E$5:$E$2004,$B43,Transactions!$D$5:$D$2004,"Expense",Transactions!$I$5:$I$2004,E$18,Transactions!$K$5:$K$2004,$D$3)) | F43: =IF($B43="","",SUMIFS(Transactions!$F$5:$F$2004,Transactions!$E$5:$E$2004,$B43,Transactions!$D$5:$D$2004,"Expense",Transactions!$I$5:$I$2004,F$18,Transactions!$K$5:$K$2004,$D$3)) | G43: =IF(B43="","",SUM(D43:F43)) | H43: =IF(B43="","",C43-G43) | I43: =IF(OR(B43="",N(C43)=0),"",G43/C43) | J43: =IF(B43="","",SUMIFS(Transactions!$F$5:$F$2004,Transactions!$E$5:$E$2004,$B43,Transactions!$D$5:$D$2004,"Expense",Transactions!$K$5:$K$2004,">="&EDATE($D$3,-2),Transactions!$K$5:$K$2004,"<="&$D$3)/3)
B44: Total | C44: =SUM(C19:C43) -> 3105 | D44: =SUM(D19:D43) -> 99.49 | E44: =SUM(E19:E43) -> 139.2 | F44: =SUM(F19:F43) -> 1318.45 | G44: =SUM(G19:G43) -> 1557.14 | H44: =SUM(H19:H43) -> 1547.86 | I44: =IF(C44=0,"",G44/C44) -> 0.50149436 | J44: =SUM(J19:J43) -> 1177.38
B45: Red = over budget, amber = 85%+ used. 3-month average covers the selected month and the two before it.
B47: Year at a glance (household)
B48: Month | C48: Income | D48: Spending | E48: Saved | F48: Left over
B49: =DATE(YEAR($D$3),1,1) -> 46023 | C49: =SUMIFS(Transactions!$F$5:$F$2004,Transactions!$D$5:$D$2004,"Income",Transactions!$K$5:$K$2004,$B49) -> 0 | D49: =SUMIFS(Transactions!$F$5:$F$2004,Transactions!$D$5:$D$2004,"Expense",Transactions!$K$5:$K$2004,$B49) -> 0 | E49: =SUMIFS('Savings Log'!$D$5:$D$1004,'Savings Log'!$G$5:$G$1004,$B49) -> 0 | F49: =C49-D49-E49 -> 0
B50: =DATE(YEAR($D$3),2,1) -> 46054 | C50: =SUMIFS(Transactions!$F$5:$F$2004,Transactions!$D$5:$D$2004,"Income",Transactions!$K$5:$K$2004,$B50) -> 0 | D50: =SUMIFS(Transactions!$F$5:$F$2004,Transactions!$D$5:$D$2004,"Expense",Transactions!$K$5:$K$2004,$B50) -> 0 | E50: =SUMIFS('Savings Log'!$D$5:$D$1004,'Savings Log'!$G$5:$G$1004,$B50) -> 0 | F50: =C50-D50-E50 -> 0
B51: =DATE(YEAR($D$3),3,1) -> 46082 | C51: =SUMIFS(Transactions!$F$5:$F$2004,Transactions!$D$5:$D$2004,"Income",Transactions!$K$5:$K$2004,$B51) -> 0 | D51: =SUMIFS(Transactions!$F$5:$F$2004,Transactions!$D$5:$D$2004,"Expense",Transactions!$K$5:$K$2004,$B51) -> 0 | E51: =SUMIFS('Savings Log'!$D$5:$D$1004,'Savings Log'!$G$5:$G$1004,$B51) -> 0 | F51: =C51-D51-E51 -> 0
B52: =DATE(YEAR($D$3),4,1) -> 46113 | C52: =SUMIFS(Transactions!$F$5:$F$2004,Transactions!$D$5:$D$2004,"Income",Transactions!$K$5:$K$2004,$B52) -> 0 | D52: =SUMIFS(Transactions!$F$5:$F$2004,Transactions!$D$5:$D$2004,"Expense",Transactions!$K$5:$K$2004,$B52) -> 0 | E52: =SUMIFS('Savings Log'!$D$5:$D$1004,'Savings Log'!$G$5:$G$1004,$B52) -> 0 | F52: =C52-D52-E52 -> 0
B53: =DATE(YEAR($D$3),5,1) -> 46143 | C53: =SUMIFS(Transactions!$F$5:$F$2004,Transactions!$D$5:$D$2004,"Income",Transactions!$K$5:$K$2004,$B53) -> 0 | D53: =SUMIFS(Transactions!$F$5:$F$2004,Transactions!$D$5:$D$2004,"Expense",Transactions!$K$5:$K$2004,$B53) -> 0 | E53: =SUMIFS('Savings Log'!$D$5:$D$1004,'Savings Log'!$G$5:$G$1004,$B53) -> 0 | F53: =C53-D53-E53 -> 0
B54: =DATE(YEAR($D$3),6,1) -> 46174 | C54: =SUMIFS(Transactions!$F$5:$F$2004,Transactions!$D$5:$D$2004,"Income",Transactions!$K$5:$K$2004,$B54) -> 0 | D54: =SUMIFS(Transactions!$F$5:$F$2004,Transactions!$D$5:$D$2004,"Expense",Transactions!$K$5:$K$2004,$B54) -> 0 | E54: =SUMIFS('Savings Log'!$D$5:$D$1004,'Savings Log'!$G$5:$G$1004,$B54) -> 0 | F54: =C54-D54-E54 -> 0
B55: =DATE(YEAR($D$3),7,1) -> 46204 | C55: =SUMIFS(Transactions!$F$5:$F$2004,Transactions!$D$5:$D$2004,"Income",Transactions!$K$5:$K$2004,$B55) -> 0 | D55: =SUMIFS(Transactions!$F$5:$F$2004,Transactions!$D$5:$D$2004,"Expense",Transactions!$K$5:$K$2004,$B55) -> 0 | E55: =SUMIFS('Savings Log'!$D$5:$D$1004,'Savings Log'!$G$5:$G$1004,$B55) -> 0 | F55: =C55-D55-E55 -> 0
...

Sheet Where to Save
A1: Where can we save?
A2: Uses the month picked on the Dashboard and your last 3 months of spending. Adjust the yellow cut % to see what trimming discretionary spending is worth.
B4: Month analysed | C4: =Dashboard!$D$3 -> 46296
B5: Cut discretionary spending by | C5: 0.2
B7: Quick stats | C7: Value | F7: Biggest discretionary categories (3-month avg) | H7: Avg / month
B8: Discretionary ('non-essential') spend this month | C8: =SUMIFS(Transactions!$F$5:$F$2004,Transactions!$L$5:$L$2004,"No",Transactions!$D$5:$D$2004,"Expense",Transactions!$K$5:$K$2004,Dashboard!$D$3) -> 174.49 | F8: =IF(LARGE($I$16:$I$40,1)<=0,"",INDEX($B$16:$B$40,MATCH(LARGE($I$16:$I$40,1),$I$16:$I$40,0))) -> Eating Out | H8: =IF(F8="","",INDEX($D$16:$D$40,MATCH(F8,$B$16:$B$40,0))) -> 98.833333
B9: ...as % of all spending this month | C9: =IF(Dashboard!G44=0,"",C8/Dashboard!G44) -> 0.112058 | F9: =IF(LARGE($I$16:$I$40,2)<=0,"",INDEX($B$16:$B$40,MATCH(LARGE($I$16:$I$40,2),$I$16:$I$40,0))) -> Takeaways | H9: =IF(F9="","",INDEX($D$16:$D$40,MATCH(F9,$B$16:$B$40,0))) -> 31.666667
B10: Categories over budget this month | C10: =COUNTIF(Dashboard!I19:I43,">1") -> 0 | F10: =IF(LARGE($I$16:$I$40,3)<=0,"",INDEX($B$16:$B$40,MATCH(LARGE($I$16:$I$40,3),$I$16:$I$40,0))) -> Shopping & Clothes | H10: =IF(F10="","",INDEX($D$16:$D$40,MATCH(F10,$B$16:$B$40,0))) -> 25
B11: Subscriptions - yearly cost | C11: =SUMIFS('Regular Bills'!$H$5:$H$64,'Regular Bills'!$D$5:$D$64,"Subscriptions",'Regular Bills'!$C$5:$C$64,"Expense") -> 250.88 | F11: =IF(LARGE($I$16:$I$40,4)<=0,"",INDEX($B$16:$B$40,MATCH(LARGE($I$16:$I$40,4),$I$16:$I$40,0))) -> Subscriptions | H11: =IF(F11="","",INDEX($D$16:$D$40,MATCH(F11,$B$16:$B$40,0))) -> 4.33
B12: All non-essential regular bills - yearly cost | C12: =SUMIFS('Regular Bills'!$H$5:$H$64,'Regular Bills'!$J$5:$J$64,"No",'Regular Bills'!$C$5:$C$64,"Expense") -> 731.88 | F12: =IF(LARGE($I$16:$I$40,5)<=0,"",INDEX($B$16:$B$40,MATCH(LARGE($I$16:$I$40,5),$I$16:$I$40,0))) | H12: =IF(F12="","",INDEX($D$16:$D$40,MATCH(F12,$B$16:$B$40,0)))
B13: Spending with no category (fix these!) | C13: =COUNTIFS(Transactions!$D$5:$D$2004,"Expense",Transactions!$E$5:$E$2004,"") -> 0 | F13: Start here: these are the easiest places to cut back.
B14: Potential yearly saving at the cut % above | C14: =SUM(H16:H40) -> 383.592
B15: Category | C15: Budget / month | D15: 3-month avg | E15: Essential? | F15: Avg vs budget | G15: Avg x 12 (yearly) | H15: Saving / year at cut % | I15: Rank helper
B16: =Dashboard!B19 -> Rent / Mortgage | C16: =Dashboard!C19 -> 1200 | D16: =Dashboard!J19 -> 800 | E16: =IF(B16="","",Settings!K14) -> Yes | F16: =IF(OR(B16="",N(C16)=0),"",D16-C16) -> -400 | G16: =IF(B16="","",D16*12) -> 9600 | H16: =IF(E16="No",G16*$C$5,"") | I16: =IF(AND(E16="No",N(D16)>0),D16+ROW()/1000000,-1) -> -1
B17: =Dashboard!B20 -> Council Tax | C17: =Dashboard!C20 -> 160 | D17: =Dashboard!J20 -> 0 | E17: =IF(B17="","",Settings!K15) -> Yes | F17: =IF(OR(B17="",N(C17)=0),"",D17-C17) -> -160 | G17: =IF(B17="","",D17*12) -> 0 | H17: =IF(E17="No",G17*$C$5,"") | I17: =IF(AND(E17="No",N(D17)>0),D17+ROW()/1000000,-1) -> -1
B18: =Dashboard!B21 -> Energy | C18: =Dashboard!C21 -> 140 | D18: =Dashboard!J21 -> 0 | E18: =IF(B18="","",Settings!K16) -> Yes | F18: =IF(OR(B18="",N(C18)=0),"",D18-C18) -> -140 | G18: =IF(B18="","",D18*12) -> 0 | H18: =IF(E18="No",G18*$C$5,"") | I18: =IF(AND(E18="No",N(D18)>0),D18+ROW()/1000000,-1) -> -1
B19: =Dashboard!B22 -> Water | C19: =Dashboard!C22 -> 40 | D19: =Dashboard!J22 -> 0 | E19: =IF(B19="","",Settings!K17) -> Yes | F19: =IF(OR(B19="",N(C19)=0),"",D19-C19) -> -40 | G19: =IF(B19="","",D19*12) -> 0 | H19: =IF(E19="No",G19*$C$5,"") | I19: =IF(AND(E19="No",N(D19)>0),D19+ROW()/1000000,-1) -> -1
B20: =Dashboard!B23 -> Broadband & Phone | C20: =Dashboard!C23 -> 70 | D20: =Dashboard!J23 -> 0 | E20: =IF(B20="","",Settings!K18) -> Yes | F20: =IF(OR(B20="",N(C20)=0),"",D20-C20) -> -70 | G20: =IF(B20="","",D20*12) -> 0 | H20: =IF(E20="No",G20*$C$5,"") | I20: =IF(AND(E20="No",N(D20)>0),D20+ROW()/1000000,-1) -> -1
B21: =Dashboard!B24 -> Insurance | C21: =Dashboard!C24 -> 60 | D21: =Dashboard!J24 -> 0 | E21: =IF(B21="","",Settings!K19) -> Yes | F21: =IF(OR(B21="",N(C21)=0),"",D21-C21) -> -60 | G21: =IF(B21="","",D21*12) -> 0 | H21: =IF(E21="No",G21*$C$5,"") | I21: =IF(AND(E21="No",N(D21)>0),D21+ROW()/1000000,-1) -> -1
B22: =Dashboard!B25 -> Groceries | C22: =Dashboard!C25 -> 450 | D22: =Dashboard!J25 -> 196.15 | E22: =IF(B22="","",Settings!K20) -> Yes | F22: =IF(OR(B22="",N(C22)=0),"",D22-C22) -> -253.85 | G22: =IF(B22="","",D22*12) -> 2353.8 | H22: =IF(E22="No",G22*$C$5,"") | I22: =IF(AND(E22="No",N(D22)>0),D22+ROW()/1000000,-1) -> -1
B23: =Dashboard!B26 -> Transport & Fuel | C23: =Dashboard!C26 -> 180 | D23: =Dashboard!J26 -> 21.4 | E23: =IF(B23="","",Settings!K21) -> Yes | F23: =IF(OR(B23="",N(C23)=0),"",D23-C23) -> -158.6 | G23: =IF(B23="","",D23*12) -> 256.8 | H23: =IF(E23="No",G23*$C$5,"") | I23: =IF(AND(E23="No",N(D23)>0),D23+ROW()/1000000,-1) -> -1
B24: =Dashboard!B27 -> Health | C24: =Dashboard!C27 -> 30 | D24: =Dashboard!J27 -> 0 | E24: =IF(B24="","",Settings!K22) -> Yes | F24: =IF(OR(B24="",N(C24)=0),"",D24-C24) -> -30 | G24: =IF(B24="","",D24*12) -> 0 | H24: =IF(E24="No",G24*$C$5,"") | I24: =IF(AND(E24="No",N(D24)>0),D24+ROW()/1000000,-1) -> -1
B25: =Dashboard!B28 -> Childcare & Kids | C25: =Dashboard!C28 -> 0 | D25: =Dashboard!J28 -> 0 | E25: =IF(B25="","",Settings!K23) -> Yes | F25: =IF(OR(B25="",N(C25)=0),"",D25-C25) | G25: =IF(B25="","",D25*12) -> 0 | H25: =IF(E25="No",G25*$C$5,"") | I25: =IF(AND(E25="No",N(D25)>0),D25+ROW()/1000000,-1) -> -1
B26: =Dashboard!B29 -> Debt Repayments | C26: =Dashboard!C29 -> 0 | D26: =Dashboard!J29 -> 0 | E26: =IF(B26="","",Settings!K24) -> Yes | F26: =IF(OR(B26="",N(C26)=0),"",D26-C26) | G26: =IF(B26="","",D26*12) -> 0 | H26: =IF(E26="No",G26*$C$5,"") | I26: =IF(AND(E26="No",N(D26)>0),D26+ROW()/1000000,-1) -> -1
B27: =Dashboard!B30 -> Eating Out | C27: =Dashboard!C30 -> 150 | D27: =Dashboard!J30 -> 98.833333 | E27: =IF(B27="","",Settings!K25) -> No | F27: =IF(OR(B27="",N(C27)=0),"",D27-C27) -> -51.166667 | G27: =IF(B27="","",D27*12) -> 1186 | H27: =IF(E27="No",G27*$C$5,"") -> 237.2 | I27: =IF(AND(E27="No",N(D27)>0),D27+ROW()/1000000,-1) -> 98.83336
... B40: =Dashboard!B43 | C40: =Dashboard!C43 | D40: =Dashboard!J43 | E40: =IF(B40="","",Settings!K38) | F40: =IF(OR(B40="",N(C40)=0),"",D40-C40) | G40: =IF(B40="","",D40*12) | H40: =IF(E40="No",G40*$C$5,"") | I40: =IF(AND(E40="No",N(D40)>0),D40+ROW()/1000000,-1) -> -1
B41: Pink 'Avg vs budget' = you're regularly spending more than planned there.

Sheet Settings
A1: Settings
A2: Set up names, accounts, categories and monthly budgets here. Yellow cells are yours to edit; everything else in the workbook updates automatically.
B3: Your name | C3: Me
B4: Partner's name | C4: Partner
B7: Account | C7: Owner | E7: Owners | H7: Category | I7: Type | J7: Monthly budget (£) | K7: Essential? | M7: Frequency | N7: Times / month | P7: Transaction types
B8: Me - Current | C8: =C3 -> Me | E8: =C3 -> Me | H8: Salary | I8: Income | M8: Weekly | N8: =52/12 -> 4.3333333 | P8: Income
B9: Partner - Current | C9: =C4 -> Partner | E9: =C4 -> Partner | H9: Bonus | I9: Income | M9: Fortnightly | N9: =26/12 -> 2.1666667 | P9: Expense
B10: Joint Account | C10: Joint | E10: Joint | H10: Side Income | I10: Income | M10: Monthly | N10: 1 | P10: Transfer
B11: Me - Credit Card | C11: =C3 -> Me | H11: Benefits | I11: Income | M11: Quarterly | N11: =1/3 -> 0.33333333
B12: Partner - Credit Card | C12: =C4 -> Partner | H12: Refunds | I12: Income | M12: Every 6 months | N12: =1/6 -> 0.16666667 | P12: Transfer = moving money between your own accounts (e.g. into Joint).
B13: Cash | C13: Joint | H13: Other Income | I13: Income | M13: Yearly | N13: =1/12 -> 0.083333333
H14: Rent / Mortgage | I14: Expense | J14: 1200 | K14: Yes
H15: Council Tax | I15: Expense | J15: 160 | K15: Yes
H16: Energy | I16: Expense | J16: 140 | K16: Yes
H17: Water | I17: Expense | J17: 40 | K17: Yes
H18: Broadband & Phone | I18: Expense | J18: 70 | K18: Yes
H19: Insurance | I19: Expense | J19: 60 | K19: Yes
H20: Groceries | I20: Expense | J20: 450 | K20: Yes
B21: Owner decides whose column the account's money appears in. Rename accounts freely - drop-downs update. | H21: Transport & Fuel | I21: Expense | J21: 180 | K21: Yes
H22: Health | I22: Expense | J22: 30 | K22: Yes
H23: Childcare & Kids | I23: Expense | J23: 0 | K23: Yes
H24: Debt Repayments | I24: Expense | J24: 0 | K24: Yes
H25: Eating Out | I25: Expense | J25: 150 | K25: No
H26: Takeaways | I26: Expense | J26: 60 | K26: No
H27: Subscriptions | I27: Expense | J27: 45 | K27: No
H28: Entertainment | I28: Expense | J28: 80 | K28: No
H29: Shopping & Clothes | I29: Expense | J29: 120 | K29: No
H30: Personal Care | I30: Expense | J30: 40 | K30: No
H31: Gifts | I31: Expense | J31: 40 | K31: No
H32: Holidays | I32: Expense | J32: 100 | K32: No
H33: Home & Garden | I33: Expense | J33: 50 | K33: No
... H35: Other | I35: Expense | J35: 50 | K35: No
I36: Expense
I37: Expense
I38: Expense
H40: Rows 8-13 are income categories, rows 14-38 expense categories. Fill blank rows to add more.

Sheet Transactions
A1: Transactions - every incoming & outgoing
A2: One row per payment. Fill the yellow columns (A-H); grey columns fill themselves. Amounts are always positive - Type says which way the money went.
A4: Date | B4: Description | C4: Account | D4: Type | E4: Category | F4: Amount (£) | G4: To account (transfers only) | H4: Notes | I4: Owner | J4: To owner | K4: Month | L4: Essential?
A5: 46266 | B5: Salary | C5: Me - Current | D5: Income | E5: Salary | F5: 2650 | H5: Example - delete | I5: =IF(C5="","",IFERROR(INDEX(Settings!$C$8:$C$19,MATCH(C5,Settings!$B$8:$B$19,0)),"?")) -> Me | J5: =IF(G5="","",IFERROR(INDEX(Settings!$C$8:$C$19,MATCH(G5,Settings!$B$8:$B$19,0)),"?")) | K5: =IF(A5="","",DATE(YEAR(A5),MONTH(A5),1)) -> 46266 | L5: =IF(E5="","",IFERROR(INDEX(Settings!$K$8:$K$38,MATCH(E5,Settings!$H$8:$H$38,0))&"",""))
A6: 46266 | B6: Salary | C6: Partner - Current | D6: Income | E6: Salary | F6: 2400 | H6: Example - delete | I6: =IF(C6="","",IFERROR(INDEX(Settings!$C$8:$C$19,MATCH(C6,Settings!$B$8:$B$19,0)),"?")) -> Partner | J6: =IF(G6="","",IFERROR(INDEX(Settings!$C$8:$C$19,MATCH(G6,Settings!$B$8:$B$19,0)),"?")) | K6: =IF(A6="","",DATE(YEAR(A6),MONTH(A6),1)) -> 46266 | L6: =IF(E6="","",IFERROR(INDEX(Settings!$K$8:$K$38,MATCH(E6,Settings!$H$8:$H$38,0))&"",""))
A7: 46266 | B7: Rent | C7: Joint Account | D7: Expense | E7: Rent / Mortgage | F7: 1200 | H7: Example - delete | I7: =IF(C7="","",IFERROR(INDEX(Settings!$C$8:$C$19,MATCH(C7,Settings!$B$8:$B$19,0)),"?")) -> Joint | J7: =IF(G7="","",IFERROR(INDEX(Settings!$C$8:$C$19,MATCH(G7,Settings!$B$8:$B$19,0)),"?")) | K7: =IF(A7="","",DATE(YEAR(A7),MONTH(A7),1)) -> 46266 | L7: =IF(E7="","",IFERROR(INDEX(Settings!$K$8:$K$38,MATCH(E7,Settings!$H$8:$H$38,0))&"","")) -> Yes
A8: 46275 | B8: Sainsbury's | C8: Joint Account | D8: Expense | E8: Groceries | F8: 470 | H8: Example - delete | I8: =IF(C8="","",IFERROR(INDEX(Settings!$C$8:$C$19,MATCH(C8,Settings!$B$8:$B$19,0)),"?")) -> Joint | J8: =IF(G8="","",IFERROR(INDEX(Settings!$C$8:$C$19,MATCH(G8,Settings!$B$8:$B$19,0)),"?")) | K8: =IF(A8="","",DATE(YEAR(A8),MONTH(A8),1)) -> 46266 | L8: =IF(E8="","",IFERROR(INDEX(Settings!$K$8:$K$38,MATCH(E8,Settings!$H$8:$H$38,0))&"","")) -> Yes
A9: 46283 | B9: Deliveroo | C9: Partner - Current | D9: Expense | E9: Takeaways | F9: 95 | H9: Example - delete | I9: =IF(C9="","",IFERROR(INDEX(Settings!$C$8:$C$19,MATCH(C9,Settings!$B$8:$B$19,0)),"?")) -> Partner | J9: =IF(G9="","",IFERROR(INDEX(Settings!$C$8:$C$19,MATCH(G9,Settings!$B$8:$B$19,0)),"?")) | K9: =IF(A9="","",DATE(YEAR(A9),MONTH(A9),1)) -> 46266 | L9: =IF(E9="","",IFERROR(INDEX(Settings!$K$8:$K$38,MATCH(E9,Settings!$H$8:$H$38,0))&"","")) -> No
A10: 46285 | B10: Restaurant | C10: Me - Credit Card | D10: Expense | E10: Eating Out | F10: 210 | H10: Example - delete | I10: =IF(C10="","",IFERROR(INDEX(Settings!$C$8:$C$19,MATCH(C10,Settings!$B$8:$B$19,0)),"?")) -> Me | J10: =IF(G10="","",IFERROR(INDEX(Settings!$C$8:$C$19,MATCH(G10,Settings!$B$8:$B$19,0)),"?")) | K10: =IF(A10="","",DATE(YEAR(A10),MONTH(A10),1)) -> 46266 | L10: =IF(E10="","",IFERROR(INDEX(Settings!$K$8:$K$38,MATCH(E10,Settings!$H$8:$H$38,0))&"","")) -> No
A11: 46296 | B11: Salary | C11: Me - Current | D11: Income | E11: Salary | F11: 2650 | H11: Example - delete | I11: =IF(C11="","",IFERROR(INDEX(Settings!$C$8:$C$19,MATCH(C11,Settings!$B$8:$B$19,0)),"?")) -> Me | J11: =IF(G11="","",IFERROR(INDEX(Settings!$C$8:$C$19,MATCH(G11,Settings!$B$8:$B$19,0)),"?")) | K11: =IF(A11="","",DATE(YEAR(A11),MONTH(A11),1)) -> 46296 | L11: =IF(E11="","",IFERROR(INDEX(Settings!$K$8:$K$38,MATCH(E11,Settings!$H$8:$H$38,0))&"",""))
A12: 46296 | B12: Salary | C12: Partner - Current | D12: Income | E12: Salary | F12: 2400 | H12: Example - delete | I12: =IF(C12="","",IFERROR(INDEX(Settings!$C$8:$C$19,MATCH(C12,Settings!$B$8:$B$19,0)),"?")) -> Partner | J12: =IF(G12="","",IFERROR(INDEX(Settings!$C$8:$C$19,MATCH(G12,Settings!$B$8:$B$19,0)),"?")) | K12: =IF(A12="","",DATE(YEAR(A12),MONTH(A12),1)) -> 46296 | L12: =IF(E12="","",IFERROR(INDEX(Settings!$K$8:$K$38,MATCH(E12,Settings!$H$8:$H$38,0))&"",""))
A13: 46296 | B13: Monthly pot to joint | C13: Me - Current | D13: Transfer | F13: 1100 | G13: Joint Account | H13: Example - delete | I13: =IF(C13="","",IFERROR(INDEX(Settings!$C$8:$C$19,MATCH(C13,Settings!$B$8:$B$19,0)),"?")) -> Me | J13: =IF(G13="","",IFERROR(INDEX(Settings!$C$8:$C$19,MATCH(G13,Settings!$B$8:$B$19,0)),"?")) -> Joint | K13: =IF(A13="","",DATE(YEAR(A13),MONTH(A13),1)) -> 46296 | L13: =IF(E13="","",IFERROR(INDEX(Settings!$K$8:$K$38,MATCH(E13,Settings!$H$8:$H$38,0))&"",""))
A14: 46296 | B14: Monthly pot to joint | C14: Partner - Current | D14: Transfer | F14: 1000 | G14: Joint Account | H14: Example - delete | I14: =IF(C14="","",IFERROR(INDEX(Settings!$C$8:$C$19,MATCH(C14,Settings!$B$8:$B$19,0)),"?")) -> Partner | J14: =IF(G14="","",IFERROR(INDEX(Settings!$C$8:$C$19,MATCH(G14,Settings!$B$8:$B$19,0)),"?")) -> Joint | K14: =IF(A14="","",DATE(YEAR(A14),MONTH(A14),1)) -> 46296 | L14: =IF(E14="","",IFERROR(INDEX(Settings!$K$8:$K$38,MATCH(E14,Settings!$H$8:$H$38,0))&"",""))
A15: 46296 | B15: Rent | C15: Joint Account | D15: Expense | E15: Rent / Mortgage | F15: 1200 | H15: Example - delete | I15: =IF(C15="","",IFERROR(INDEX(Settings!$C$8:$C$19,MATCH(C15,Settings!$B$8:$B$19,0)),"?")) -> Joint | J15: =IF(G15="","",IFERROR(INDEX(Settings!$C$8:$C$19,MATCH(G15,Settings!$B$8:$B$19,0)),"?")) | K15: =IF(A15="","",DATE(YEAR(A15),MONTH(A15),1)) -> 46296 | L15: =IF(E15="","",IFERROR(INDEX(Settings!$K$8:$K$38,MATCH(E15,Settings!$H$8:$H$38,0))&"","")) -> Yes
A16: 46298 | B16: Aldi big shop | C16: Joint Account | D16: Expense | E16: Groceries | F16: 118.45 | H16: Example - delete | I16: =IF(C16="","",IFERROR(INDEX(Settings!$C$8:$C$19,MATCH(C16,Settings!$B$8:$B$19,0)),"?")) -> Joint | J16: =IF(G16="","",IFERROR(INDEX(Settings!$C$8:$C$19,MATCH(G16,Settings!$B$8:$B$19,0)),"?")) | K16: =IF(A16="","",DATE(YEAR(A16),MONTH(A16),1)) -> 46296 | L16: =IF(E16="","",IFERROR(INDEX(Settings!$K$8:$K$38,MATCH(E16,Settings!$H$8:$H$38,0))&"","")) -> Yes
A17: 46299 | B17: Netflix | C17: Me - Credit Card | D17: Expense | E17: Subscriptions | F17: 12.99 | H17: Example - delete | I17: =IF(C17="","",IFERROR(INDEX(Settings!$C$8:$C$19,MATCH(C17,Settings!$B$8:$B$19,0)),"?")) -> Me | J17: =IF(G17="","",IFERROR(INDEX(Settings!$C$8:$C$19,MATCH(G17,Settings!$B$8:$B$19,0)),"?")) | K17: =IF(A17="","",DATE(YEAR(A17),MONTH(A17),1)) -> 46296 | L17: =IF(E17="","",IFERROR(INDEX(Settings!$K$8:$K$38,MATCH(E17,Settings!$H$8:$H$38,0))&"","")) -> No
A18: 46300 | B18: Train to work | C18: Partner - Current | D18: Expense | E18: Transport & Fuel | F18: 64.2 | H18: Example - delete | I18: =IF(C18="","",IFERROR(INDEX(Settings!$C$8:$C$19,MATCH(C18,Settings!$B$8:$B$19,0)),"?")) -> Partner | J18: =IF(G18="","",IFERROR(INDEX(Settings!$C$8:$C$19,MATCH(G18,Settings!$B$8:$B$19,0)),"?")) | K18: =IF(A18="","",DATE(YEAR(A18),MONTH(A18),1)) -> 46296 | L18: =IF(E18="","",IFERROR(INDEX(Settings!$K$8:$K$38,MATCH(E18,Settings!$H$8:$H$38,0))&"","")) -> Yes
A19: 46301 | B19: Dinner out | C19: Me - Credit Card | D19: Expense | E19: Eating Out | F19: 86.5 | H19: Example - delete | I19: =IF(C19="","",IFERROR(INDEX(Settings!$C$8:$C$19,MATCH(C19,Settings!$B$8:$B$19,0)),"?")) -> Me | J19: =IF(G19="","",IFERROR(INDEX(Settings!$C$8:$C$19,MATCH(G19,Settings!$B$8:$B$19,0)),"?")) | K19: =IF(A19="","",DATE(YEAR(A19),MONTH(A19),1)) -> 46296 | L19: =IF(E19="","",IFERROR(INDEX(Settings!$K$8:$K$38,MATCH(E19,Settings!$H$8:$H$38,0))&"","")) -> No
A20: 46302 | B20: New trainers | C20: Partner - Credit Card | D20: Expense | E20: Shopping & Clothes | F20: 75 | H20: Example - delete | I20: =IF(C20="","",IFERROR(INDEX(Settings!$C$8:$C$19,MATCH(C20,Settings!$B$8:$B$19,0)),"?")) -> Partner | J20: =IF(G20="","",IFERROR(INDEX(Settings!$C$8:$C$19,MATCH(G20,Settings!$B$8:$B$19,0)),"?")) | K20: =IF(A20="","",DATE(YEAR(A20),MONTH(A20),1)) -> 46296 | L20: =IF(E20="","",IFERROR(INDEX(Settings!$K$8:$K$38,MATCH(E20,Settings!$H$8:$H$38,0))&"","")) -> No
I21: =IF(C21="","",IFERROR(INDEX(Settings!$C$8:$C$19,MATCH(C21,Settings!$B$8:$B$19,0)),"?")) | J21: =IF(G21="","",IFERROR(INDEX(Settings!$C$8:$C$19,MATCH(G21,Settings!$B$8:$B$19,0)),"?")) | K21: =IF(A21="","",DATE(YEAR(A21),MONTH(A21),1)) | L21: =IF(E21="","",IFERROR(INDEX(Settings!$K$8:$K$38,MATCH(E21,Settings!$H$8:$H$38,0))&"",""))
I22: =IF(C22="","",IFERROR(INDEX(Settings!$C$8:$C$19,MATCH(C22,Settings!$B$8:$B$19,0)),"?")) | J22: =IF(G22="","",IFERROR(INDEX(Settings!$C$8:$C$19,MATCH(G22,Settings!$B$8:$B$19,0)),"?")) | K22: =IF(A22="","",DATE(YEAR(A22),MONTH(A22),1)) | L22: =IF(E22="","",IFERROR(INDEX(Settings!$K$8:$K$38,MATCH(E22,Settings!$H$8:$H$38,0))&"",""))
I23: =IF(C23="","",IFERROR(INDEX(Settings!$C$8:$C$19,MATCH(C23,Settings!$B$8:$B$19,0)),"?")) | J23: =IF(G23="","",IFERROR(INDEX(Settings!$C$8:$C$19,MATCH(G23,Settings!$B$8:$B$19,0)),"?")) | K23: =IF(A23="","",DATE(YEAR(A23),MONTH(A23),1)) | L23: =IF(E23="","",IFERROR(INDEX(Settings!$K$8:$K$38,MATCH(E23,Settings!$H$8:$H$38,0))&"",""))
I24: =IF(C24="","",IFERROR(INDEX(Settings!$C$8:$C$19,MATCH(C24,Settings!$B$8:$B$19,0)),"?")) | J24: =IF(G24="","",IFERROR(INDEX(Settings!$C$8:$C$19,MATCH(G24,Settings!$B$8:$B$19,0)),"?")) | K24: =IF(A24="","",DATE(YEAR(A24),MONTH(A24),1)) | L24: =IF(E24="","",IFERROR(INDEX(Settings!$K$8:$K$38,MATCH(E24,Settings!$H$8:$H$38,0))&"",""))
I25: =IF(C25="","",IFERROR(INDEX(Settings!$C$8:$C$19,MATCH(C25,Settings!$B$8:$B$19,0)),"?")) | J25: =IF(G25="","",IFERROR(INDEX(Settings!$C$8:$C$19,MATCH(G25,Settings!$B$8:$B$19,0)),"?")) | K25: =IF(A25="","",DATE(YEAR(A25),MONTH(A25),1)) | L25: =IF(E25="","",IFERROR(INDEX(Settings!$K$8:$K$38,MATCH(E25,Settings!$H$8:$H$38,0))&"",""))
I26: =IF(C26="","",IFERROR(INDEX(Settings!$C$8:$C$19,MATCH(C26,Settings!$B$8:$B$19,0)),"?")) | J26: =IF(G26="","",IFERROR(INDEX(Settings!$C$8:$C$19,MATCH(G26,Settings!$B$8:$B$19,0)),"?")) | K26: =IF(A26="","",DATE(YEAR(A26),MONTH(A26),1)) | L26: =IF(E26="","",IFERROR(INDEX(Settings!$K$8:$K$38,MATCH(E26,Settings!$H$8:$H$38,0))&"",""))
I27: =IF(C27="","",IFERROR(INDEX(Settings!$C$8:$C$19,MATCH(C27,Settings!$B$8:$B$19,0)),"?")) | J27: =IF(G27="","",IFERROR(INDEX(Settings!$C$8:$C$19,MATCH(G27,Settings!$B$8:$B$19,0)),"?")) | K27: =IF(A27="","",DATE(YEAR(A27),MONTH(A27),1)) | L27: =IF(E27="","",IFERROR(INDEX(Settings!$K$8:$K$38,MATCH(E27,Settings!$H$8:$H$38,0))&"",""))
I28: =IF(C28="","",IFERROR(INDEX(Settings!$C$8:$C$19,MATCH(C28,Settings!$B$8:$B$19,0)),"?")) | J28: =IF(G28="","",IFERROR(INDEX(Settings!$C$8:$C$19,MATCH(G28,Settings!$B$8:$B$19,0)),"?")) | K28: =IF(A28="","",DATE(YEAR(A28),MONTH(A28),1)) | L28: =IF(E28="","",IFERROR(INDEX(Settings!$K$8:$K$38,MATCH(E28,Settings!$H$8:$H$38,0))&"",""))
I29: =IF(C29="","",IFERROR(INDEX(Settings!$C$8:$C$19,MATCH(C29,Settings!$B$8:$B$19,0)),"?")) | J29: =IF(G29="","",IFERROR(INDEX(Settings!$C$8:$C$19,MATCH(G29,Settings!$B$8:$B$19,0)),"?")) | K29: =IF(A29="","",DATE(YEAR(A29),MONTH(A29),1)) | L29: =IF(E29="","",IFERROR(INDEX(Settings!$K$8:$K$38,MATCH(E29,Settings!$H$8:$H$38,0))&"",""))
I30: =IF(C30="","",IFERROR(INDEX(Settings!$C$8:$C$19,MATCH(C30,Settings!$B$8:$B$19,0)),"?")) | J30: =IF(G30="","",IFERROR(INDEX(Settings!$C$8:$C$19,MATCH(G30,Settings!$B$8:$B$19,0)),"?")) | K30: =IF(A30="","",DATE(YEAR(A30),MONTH(A30),1)) | L30: =IF(E30="","",IFERROR(INDEX(Settings!$K$8:$K$38,MATCH(E30,Settings!$H$8:$H$38,0))&"",""))
I31: =IF(C31="","",IFERROR(INDEX(Settings!$C$8:$C$19,MATCH(C31,Settings!$B$8:$B$19,0)),"?")) | J31: =IF(G31="","",IFERROR(INDEX(Settings!$C$8:$C$19,MATCH(G31,Settings!$B$8:$B$19,0)),"?")) | K31: =IF(A31="","",DATE(YEAR(A31),MONTH(A31),1)) | L31: =IF(E31="","",IFERROR(INDEX(Settings!$K$8:$K$38,MATCH(E31,Settings!$H$8:$H$38,0))&"",""))
I32: =IF(C32="","",IFERROR(INDEX(Settings!$C$8:$C$19,MATCH(C32,Settings!$B$8:$B$19,0)),"?")) | J32: =IF(G32="","",IFERROR(INDEX(Settings!$C$8:$C$19,MATCH(G32,Settings!$B$8:$B$19,0)),"?")) | K32: =IF(A32="","",DATE(YEAR(A32),MONTH(A32),1)) | L32: =IF(E32="","",IFERROR(INDEX(Settings!$K$8:$K$38,MATCH(E32,Settings!$H$8:$H$38,0))&"",""))
... I2004: =IF(C2004="","",IFERROR(INDEX(Settings!$C$8:$C$19,MATCH(C2004,Settings!$B$8:$B$19,0)),"?")) | J2004: =IF(G2004="","",IFERROR(INDEX(Settings!$C$8:$C$19,MATCH(G2004,Settings!$B$8:$B$19,0)),"?")) | K2004: =IF(A2004="","",DATE(YEAR(A2004),MONTH(A2004),1)) | L2004: =IF(E2004="","",IFERROR(INDEX(Settings!$K$8:$K$38,MATCH(E2004,Settings!$H$8:$H$38,0))&"",""))

Sheet Regular Bills
A1: Regular bills, subscriptions & income
A2: List anything that repeats (salary, rent, phone, gym, Netflix...). It is converted to a monthly & yearly cost so you can see what you're committed to - and what you could cancel.
A4: Item | B4: Account | C4: Type | D4: Category | E4: Amount (£) | F4: Frequency | G4: Per month | H4: Per year | I4: Owner | J4: Essential? | K4: Review notes
A5: Salary | B5: Me - Current | C5: Income | D5: Salary | E5: 2650 | F5: Monthly | G5: =IF(OR(E5="",F5=""),"",E5*IFERROR(INDEX(Settings!$N$8:$N$13,MATCH(F5,Settings!$M$8:$M$13,0)),0)) -> 2650 | H5: =IF(G5="","",G5*12) -> 31800 | I5: =IF(B5="","",IFERROR(INDEX(Settings!$C$8:$C$19,MATCH(B5,Settings!$B$8:$B$19,0)),"?")) -> Me | J5: =IF(D5="","",IFERROR(INDEX(Settings!$K$8:$K$38,MATCH(D5,Settings!$H$8:$H$38,0))&"",""))
A6: Salary | B6: Partner - Current | C6: Income | D6: Salary | E6: 2400 | F6: Monthly | G6: =IF(OR(E6="",F6=""),"",E6*IFERROR(INDEX(Settings!$N$8:$N$13,MATCH(F6,Settings!$M$8:$M$13,0)),0)) -> 2400 | H6: =IF(G6="","",G6*12) -> 28800 | I6: =IF(B6="","",IFERROR(INDEX(Settings!$C$8:$C$19,MATCH(B6,Settings!$B$8:$B$19,0)),"?")) -> Partner | J6: =IF(D6="","",IFERROR(INDEX(Settings!$K$8:$K$38,MATCH(D6,Settings!$H$8:$H$38,0))&"",""))
A7: Rent | B7: Joint Account | C7: Expense | D7: Rent / Mortgage | E7: 1200 | F7: Monthly | G7: =IF(OR(E7="",F7=""),"",E7*IFERROR(INDEX(Settings!$N$8:$N$13,MATCH(F7,Settings!$M$8:$M$13,0)),0)) -> 1200 | H7: =IF(G7="","",G7*12) -> 14400 | I7: =IF(B7="","",IFERROR(INDEX(Settings!$C$8:$C$19,MATCH(B7,Settings!$B$8:$B$19,0)),"?")) -> Joint | J7: =IF(D7="","",IFERROR(INDEX(Settings!$K$8:$K$38,MATCH(D7,Settings!$H$8:$H$38,0))&"","")) -> Yes
A8: Council tax | B8: Joint Account | C8: Expense | D8: Council Tax | E8: 160 | F8: Monthly | G8: =IF(OR(E8="",F8=""),"",E8*IFERROR(INDEX(Settings!$N$8:$N$13,MATCH(F8,Settings!$M$8:$M$13,0)),0)) -> 160 | H8: =IF(G8="","",G8*12) -> 1920 | I8: =IF(B8="","",IFERROR(INDEX(Settings!$C$8:$C$19,MATCH(B8,Settings!$B$8:$B$19,0)),"?")) -> Joint | J8: =IF(D8="","",IFERROR(INDEX(Settings!$K$8:$K$38,MATCH(D8,Settings!$H$8:$H$38,0))&"","")) -> Yes
A9: Gas & electric | B9: Joint Account | C9: Expense | D9: Energy | E9: 140 | F9: Monthly | G9: =IF(OR(E9="",F9=""),"",E9*IFERROR(INDEX(Settings!$N$8:$N$13,MATCH(F9,Settings!$M$8:$M$13,0)),0)) -> 140 | H9: =IF(G9="","",G9*12) -> 1680 | I9: =IF(B9="","",IFERROR(INDEX(Settings!$C$8:$C$19,MATCH(B9,Settings!$B$8:$B$19,0)),"?")) -> Joint | J9: =IF(D9="","",IFERROR(INDEX(Settings!$K$8:$K$38,MATCH(D9,Settings!$H$8:$H$38,0))&"","")) -> Yes | K9: Compare tariffs at renewal
A10: Broadband | B10: Joint Account | C10: Expense | D10: Broadband & Phone | E10: 35 | F10: Monthly | G10: =IF(OR(E10="",F10=""),"",E10*IFERROR(INDEX(Settings!$N$8:$N$13,MATCH(F10,Settings!$M$8:$M$13,0)),0)) -> 35 | H10: =IF(G10="","",G10*12) -> 420 | I10: =IF(B10="","",IFERROR(INDEX(Settings!$C$8:$C$19,MATCH(B10,Settings!$B$8:$B$19,0)),"?")) -> Joint | J10: =IF(D10="","",IFERROR(INDEX(Settings!$K$8:$K$38,MATCH(D10,Settings!$H$8:$H$38,0))&"","")) -> Yes | K10: Contract ends Mar - haggle
A11: Netflix | B11: Me - Credit Card | C11: Expense | D11: Subscriptions | E11: 12.99 | F11: Monthly | G11: =IF(OR(E11="",F11=""),"",E11*IFERROR(INDEX(Settings!$N$8:$N$13,MATCH(F11,Settings!$M$8:$M$13,0)),0)) -> 12.99 | H11: =IF(G11="","",G11*12) -> 155.88 | I11: =IF(B11="","",IFERROR(INDEX(Settings!$C$8:$C$19,MATCH(B11,Settings!$B$8:$B$19,0)),"?")) -> Me | J11: =IF(D11="","",IFERROR(INDEX(Settings!$K$8:$K$38,MATCH(D11,Settings!$H$8:$H$38,0))&"","")) -> No | K11: Still watching?
A12: Gym | B12: Partner - Current | C12: Expense | D12: Hobbies | E12: 9.25 | F12: Weekly | G12: =IF(OR(E12="",F12=""),"",E12*IFERROR(INDEX(Settings!$N$8:$N$13,MATCH(F12,Settings!$M$8:$M$13,0)),0)) -> 40.083333 | H12: =IF(G12="","",G12*12) -> 481 | I12: =IF(B12="","",IFERROR(INDEX(Settings!$C$8:$C$19,MATCH(B12,Settings!$B$8:$B$19,0)),"?")) -> Partner | J12: =IF(D12="","",IFERROR(INDEX(Settings!$K$8:$K$38,MATCH(D12,Settings!$H$8:$H$38,0))&"","")) -> No
A13: Car insurance | B13: Joint Account | C13: Expense | D13: Insurance | E13: 540 | F13: Yearly | G13: =IF(OR(E13="",F13=""),"",E13*IFERROR(INDEX(Settings!$N$8:$N$13,MATCH(F13,Settings!$M$8:$M$13,0)),0)) -> 45 | H13: =IF(G13="","",G13*12) -> 540 | I13: =IF(B13="","",IFERROR(INDEX(Settings!$C$8:$C$19,MATCH(B13,Settings!$B$8:$B$19,0)),"?")) -> Joint | J13: =IF(D13="","",IFERROR(INDEX(Settings!$K$8:$K$38,MATCH(D13,Settings!$H$8:$H$38,0))&"","")) -> Yes
A14: Amazon Prime | B14: Me - Credit Card | C14: Expense | D14: Subscriptions | E14: 95 | F14: Yearly | G14: =IF(OR(E14="",F14=""),"",E14*IFERROR(INDEX(Settings!$N$8:$N$13,MATCH(F14,Settings!$M$8:$M$13,0)),0)) -> 7.9166667 | H14: =IF(G14="","",G14*12) -> 95 | I14: =IF(B14="","",IFERROR(INDEX(Settings!$C$8:$C$19,MATCH(B14,Settings!$B$8:$B$19,0)),"?")) -> Me | J14: =IF(D14="","",IFERROR(INDEX(Settings!$K$8:$K$38,MATCH(D14,Settings!$H$8:$H$38,0))&"","")) -> No
G15: =IF(OR(E15="",F15=""),"",E15*IFERROR(INDEX(Settings!$N$8:$N$13,MATCH(F15,Settings!$M$8:$M$13,0)),0)) | H15: =IF(G15="","",G15*12) | I15: =IF(B15="","",IFERROR(INDEX(Settings!$C$8:$C$19,MATCH(B15,Settings!$B$8:$B$19,0)),"?")) | J15: =IF(D15="","",IFERROR(INDEX(Settings!$K$8:$K$38,MATCH(D15,Settings!$H$8:$H$38,0))&"",""))
G16: =IF(OR(E16="",F16=""),"",E16*IFERROR(INDEX(Settings!$N$8:$N$13,MATCH(F16,Settings!$M$8:$M$13,0)),0)) | H16: =IF(G16="","",G16*12) | I16: =IF(B16="","",IFERROR(INDEX(Settings!$C$8:$C$19,MATCH(B16,Settings!$B$8:$B$19,0)),"?")) | J16: =IF(D16="","",IFERROR(INDEX(Settings!$K$8:$K$38,MATCH(D16,Settings!$H$8:$H$38,0))&"",""))
G17: =IF(OR(E17="",F17=""),"",E17*IFERROR(INDEX(Settings!$N$8:$N$13,MATCH(F17,Settings!$M$8:$M$13,0)),0)) | H17: =IF(G17="","",G17*12) | I17: =IF(B17="","",IFERROR(INDEX(Settings!$C$8:$C$19,MATCH(B17,Settings!$B$8:$B$19,0)),"?")) | J17: =IF(D17="","",IFERROR(INDEX(Settings!$K$8:$K$38,MATCH(D17,Settings!$H$8:$H$38,0))&"",""))
G18: =IF(OR(E18="",F18=""),"",E18*IFERROR(INDEX(Settings!$N$8:$N$13,MATCH(F18,Settings!$M$8:$M$13,0)),0)) | H18: =IF(G18="","",G18*12) | I18: =IF(B18="","",IFERROR(INDEX(Settings!$C$8:$C$19,MATCH(B18,Settings!$B$8:$B$19,0)),"?")) | J18: =IF(D18="","",IFERROR(INDEX(Settings!$K$8:$K$38,MATCH(D18,Settings!$H$8:$H$38,0))&"",""))
G19: =IF(OR(E19="",F19=""),"",E19*IFERROR(INDEX(Settings!$N$8:$N$13,MATCH(F19,Settings!$M$8:$M$13,0)),0)) | H19: =IF(G19="","",G19*12) | I19: =IF(B19="","",IFERROR(INDEX(Settings!$C$8:$C$19,MATCH(B19,Settings!$B$8:$B$19,0)),"?")) | J19: =IF(D19="","",IFERROR(INDEX(Settings!$K$8:$K$38,MATCH(D19,Settings!$H$8:$H$38,0))&"",""))
G20: =IF(OR(E20="",F20=""),"",E20*IFERROR(INDEX(Settings!$N$8:$N$13,MATCH(F20,Settings!$M$8:$M$13,0)),0)) | H20: =IF(G20="","",G20*12) | I20: =IF(B20="","",IFERROR(INDEX(Settings!$C$8:$C$19,MATCH(B20,Settings!$B$8:$B$19,0)),"?")) | J20: =IF(D20="","",IFERROR(INDEX(Settings!$K$8:$K$38,MATCH(D20,Settings!$H$8:$H$38,0))&"",""))
G21: =IF(OR(E21="",F21=""),"",E21*IFERROR(INDEX(Settings!$N$8:$N$13,MATCH(F21,Settings!$M$8:$M$13,0)),0)) | H21: =IF(G21="","",G21*12) | I21: =IF(B21="","",IFERROR(INDEX(Settings!$C$8:$C$19,MATCH(B21,Settings!$B$8:$B$19,0)),"?")) | J21: =IF(D21="","",IFERROR(INDEX(Settings!$K$8:$K$38,MATCH(D21,Settings!$H$8:$H$38,0))&"",""))
G22: =IF(OR(E22="",F22=""),"",E22*IFERROR(INDEX(Settings!$N$8:$N$13,MATCH(F22,Settings!$M$8:$M$13,0)),0)) | H22: =IF(G22="","",G22*12) | I22: =IF(B22="","",IFERROR(INDEX(Settings!$C$8:$C$19,MATCH(B22,Settings!$B$8:$B$19,0)),"?")) | J22: =IF(D22="","",IFERROR(INDEX(Settings!$K$8:$K$38,MATCH(D22,Settings!$H$8:$H$38,0))&"",""))
G23: =IF(OR(E23="",F23=""),"",E23*IFERROR(INDEX(Settings!$N$8:$N$13,MATCH(F23,Settings!$M$8:$M$13,0)),0)) | H23: =IF(G23="","",G23*12) | I23: =IF(B23="","",IFERROR(INDEX(Settings!$C$8:$C$19,MATCH(B23,Settings!$B$8:$B$19,0)),"?")) | J23: =IF(D23="","",IFERROR(INDEX(Settings!$K$8:$K$38,MATCH(D23,Settings!$H$8:$H$38,0))&"",""))
G24: =IF(OR(E24="",F24=""),"",E24*IFERROR(INDEX(Settings!$N$8:$N$13,MATCH(F24,Settings!$M$8:$M$13,0)),0)) | H24: =IF(G24="","",G24*12) | I24: =IF(B24="","",IFERROR(INDEX(Settings!$C$8:$C$19,MATCH(B24,Settings!$B$8:$B$19,0)),"?")) | J24: =IF(D24="","",IFERROR(INDEX(Settings!$K$8:$K$38,MATCH(D24,Settings!$H$8:$H$38,0))&"",""))
G25: =IF(OR(E25="",F25=""),"",E25*IFERROR(INDEX(Settings!$N$8:$N$13,MATCH(F25,Settings!$M$8:$M$13,0)),0)) | H25: =IF(G25="","",G25*12) | I25: =IF(B25="","",IFERROR(INDEX(Settings!$C$8:$C$19,MATCH(B25,Settings!$B$8:$B$19,0)),"?")) | J25: =IF(D25="","",IFERROR(INDEX(Settings!$K$8:$K$38,MATCH(D25,Settings!$H$8:$H$38,0))&"",""))
G26: =IF(OR(E26="",F26=""),"",E26*IFERROR(INDEX(Settings!$N$8:$N$13,MATCH(F26,Settings!$M$8:$M$13,0)),0)) | H26: =IF(G26="","",G26*12) | I26: =IF(B26="","",IFERROR(INDEX(Settings!$C$8:$C$19,MATCH(B26,Settings!$B$8:$B$19,0)),"?")) | J26: =IF(D26="","",IFERROR(INDEX(Settings!$K$8:$K$38,MATCH(D26,Settings!$H$8:$H$38,0))&"",""))
... G64: =IF(OR(E64="",F64=""),"",E64*IFERROR(INDEX(Settings!$N$8:$N$13,MATCH(F64,Settings!$M$8:$M$13,0)),0)) | H64: =IF(G64="","",G64*12) | I64: =IF(B64="","",IFERROR(INDEX(Settings!$C$8:$C$19,MATCH(B64,Settings!$B$8:$B$19,0)),"?")) | J64: =IF(D64="","",IFERROR(INDEX(Settings!$K$8:$K$38,MATCH(D64,Settings!$H$8:$H$38,0))&"",""))

Sheet Savings
A1: Savings goals
A2: Set a goal, target and date. Log every deposit/withdrawal on the 'Savings Log' tab - progress and the monthly amount needed update automatically.
A3: Today | B3: =TODAY() -> 46306
A5: Goal | B5: Owner | C5: Target (£) | D5: Target date | E5: Starting balance (£) | F5: Added since (£) | G5: Current balance (£) | H5: Still to save (£) | I5: % complete | J5: Months left | K5: Needed per month (£)
A6: Emergency fund | B6: Joint | C6: 6000 | D6: 46568 | E6: 1500 | F6: =IF(A6="","",SUMIFS('Savings Log'!$D$5:$D$1004,'Savings Log'!$B$5:$B$1004,A6)) -> 600 | G6: =IF(A6="","",E6+F6) -> 2100 | H6: =IF(A6="","",MAX(0,C6-G6)) -> 3900 | I6: =IF(OR(A6="",N(C6)=0),"",MIN(1,G6/C6)) -> 0.35 | J6: =IF(OR(A6="",D6=""),"",MAX(0,(YEAR(D6)-YEAR($B$3))*12+MONTH(D6)-MONTH($B$3))) -> 8 | K6: =IF(OR(A6="",D6=""),"",IF(H6=0,0,IF(J6=0,H6,H6/J6))) -> 487.5
A7: Holiday 2027 | B7: Joint | C7: 2500 | D7: 46569 | E7: 200 | F7: =IF(A7="","",SUMIFS('Savings Log'!$D$5:$D$1004,'Savings Log'!$B$5:$B$1004,A7)) -> 300 | G7: =IF(A7="","",E7+F7) -> 500 | H7: =IF(A7="","",MAX(0,C7-G7)) -> 2000 | I7: =IF(OR(A7="",N(C7)=0),"",MIN(1,G7/C7)) -> 0.2 | J7: =IF(OR(A7="",D7=""),"",MAX(0,(YEAR(D7)-YEAR($B$3))*12+MONTH(D7)-MONTH($B$3))) -> 9 | K7: =IF(OR(A7="",D7=""),"",IF(H7=0,0,IF(J7=0,H7,H7/J7))) -> 222.22222
A8: New car | B8: =Settings!C3 -> Me | C8: 4000 | D8: 46753 | E8: 0 | F8: =IF(A8="","",SUMIFS('Savings Log'!$D$5:$D$1004,'Savings Log'!$B$5:$B$1004,A8)) -> 200 | G8: =IF(A8="","",E8+F8) -> 200 | H8: =IF(A8="","",MAX(0,C8-G8)) -> 3800 | I8: =IF(OR(A8="",N(C8)=0),"",MIN(1,G8/C8)) -> 0.05 | J8: =IF(OR(A8="",D8=""),"",MAX(0,(YEAR(D8)-YEAR($B$3))*12+MONTH(D8)-MONTH($B$3))) -> 15 | K8: =IF(OR(A8="",D8=""),"",IF(H8=0,0,IF(J8=0,H8,H8/J8))) -> 253.33333
F9: =IF(A9="","",SUMIFS('Savings Log'!$D$5:$D$1004,'Savings Log'!$B$5:$B$1004,A9)) | G9: =IF(A9="","",E9+F9) | H9: =IF(A9="","",MAX(0,C9-G9)) | I9: =IF(OR(A9="",N(C9)=0),"",MIN(1,G9/C9)) | J9: =IF(OR(A9="",D9=""),"",MAX(0,(YEAR(D9)-YEAR($B$3))*12+MONTH(D9)-MONTH($B$3))) | K9: =IF(OR(A9="",D9=""),"",IF(H9=0,0,IF(J9=0,H9,H9/J9)))
F10: =IF(A10="","",SUMIFS('Savings Log'!$D$5:$D$1004,'Savings Log'!$B$5:$B$1004,A10)) | G10: =IF(A10="","",E10+F10) | H10: =IF(A10="","",MAX(0,C10-G10)) | I10: =IF(OR(A10="",N(C10)=0),"",MIN(1,G10/C10)) | J10: =IF(OR(A10="",D10=""),"",MAX(0,(YEAR(D10)-YEAR($B$3))*12+MONTH(D10)-MONTH($B$3))) | K10: =IF(OR(A10="",D10=""),"",IF(H10=0,0,IF(J10=0,H10,H10/J10)))
F11: =IF(A11="","",SUMIFS('Savings Log'!$D$5:$D$1004,'Savings Log'!$B$5:$B$1004,A11)) | G11: =IF(A11="","",E11+F11) | H11: =IF(A11="","",MAX(0,C11-G11)) | I11: =IF(OR(A11="",N(C11)=0),"",MIN(1,G11/C11)) | J11: =IF(OR(A11="",D11=""),"",MAX(0,(YEAR(D11)-YEAR($B$3))*12+MONTH(D11)-MONTH($B$3))) | K11: =IF(OR(A11="",D11=""),"",IF(H11=0,0,IF(J11=0,H11,H11/J11)))
F12: =IF(A12="","",SUMIFS('Savings Log'!$D$5:$D$1004,'Savings Log'!$B$5:$B$1004,A12)) | G12: =IF(A12="","",E12+F12) | H12: =IF(A12="","",MAX(0,C12-G12)) | I12: =IF(OR(A12="",N(C12)=0),"",MIN(1,G12/C12)) | J12: =IF(OR(A12="",D12=""),"",MAX(0,(YEAR(D12)-YEAR($B$3))*12+MONTH(D12)-MONTH($B$3))) | K12: =IF(OR(A12="",D12=""),"",IF(H12=0,0,IF(J12=0,H12,H12/J12)))
F13: =IF(A13="","",SUMIFS('Savings Log'!$D$5:$D$1004,'Savings Log'!$B$5:$B$1004,A13)) | G13: =IF(A13="","",E13+F13) | H13: =IF(A13="","",MAX(0,C13-G13)) | I13: =IF(OR(A13="",N(C13)=0),"",MIN(1,G13/C13)) | J13: =IF(OR(A13="",D13=""),"",MAX(0,(YEAR(D13)-YEAR($B$3))*12+MONTH(D13)-MONTH($B$3))) | K13: =IF(OR(A13="",D13=""),"",IF(H13=0,0,IF(J13=0,H13,H13/J13)))
F14: =IF(A14="","",SUMIFS('Savings Log'!$D$5:$D$1004,'Savings Log'!$B$5:$B$1004,A14)) | G14: =IF(A14="","",E14+F14) | H14: =IF(A14="","",MAX(0,C14-G14)) | I14: =IF(OR(A14="",N(C14)=0),"",MIN(1,G14/C14)) | J14: =IF(OR(A14="",D14=""),"",MAX(0,(YEAR(D14)-YEAR($B$3))*12+MONTH(D14)-MONTH($B$3))) | K14: =IF(OR(A14="",D14=""),"",IF(H14=0,0,IF(J14=0,H14,H14/J14)))
F15: =IF(A15="","",SUMIFS('Savings Log'!$D$5:$D$1004,'Savings Log'!$B$5:$B$1004,A15)) | G15: =IF(A15="","",E15+F15) | H15: =IF(A15="","",MAX(0,C15-G15)) | I15: =IF(OR(A15="",N(C15)=0),"",MIN(1,G15/C15)) | J15: =IF(OR(A15="",D15=""),"",MAX(0,(YEAR(D15)-YEAR($B$3))*12+MONTH(D15)-MONTH($B$3))) | K15: =IF(OR(A15="",D15=""),"",IF(H15=0,0,IF(J15=0,H15,H15/J15)))
F16: =IF(A16="","",SUMIFS('Savings Log'!$D$5:$D$1004,'Savings Log'!$B$5:$B$1004,A16)) | G16: =IF(A16="","",E16+F16) | H16: =IF(A16="","",MAX(0,C16-G16)) | I16: =IF(OR(A16="",N(C16)=0),"",MIN(1,G16/C16)) | J16: =IF(OR(A16="",D16=""),"",MAX(0,(YEAR(D16)-YEAR($B$3))*12+MONTH(D16)-MONTH($B$3))) | K16: =IF(OR(A16="",D16=""),"",IF(H16=0,0,IF(J16=0,H16,H16/J16)))
F17: =IF(A17="","",SUMIFS('Savings Log'!$D$5:$D$1004,'Savings Log'!$B$5:$B$1004,A17)) | G17: =IF(A17="","",E17+F17) | H17: =IF(A17="","",MAX(0,C17-G17)) | I17: =IF(OR(A17="",N(C17)=0),"",MIN(1,G17/C17)) | J17: =IF(OR(A17="",D17=""),"",MAX(0,(YEAR(D17)-YEAR($B$3))*12+MONTH(D17)-MONTH($B$3))) | K17: =IF(OR(A17="",D17=""),"",IF(H17=0,0,IF(J17=0,H17,H17/J17)))
A18: Total | C18: =SUM(C6:C17) -> 12500 | E18: =SUM(E6:E17) -> 1700 | F18: =SUM(F6:F17) -> 1100 | G18: =SUM(G6:G17) -> 2800 | H18: =SUM(H6:H17) -> 9700 | I18: =IF(C18=0,"",G18/C18) -> 0.224 | K18: =SUM(K6:K17) -> 963.05556

Sheet Savings Log
A1: Savings log
A2: Every time you put money into (or take it out of) savings, add a row. Use a negative amount for a withdrawal.
A4: Date | B4: Goal | C4: From account | D4: Amount (£) | E4: Notes | F4: Owner | G4: Month
A5: 46264 | B5: Emergency fund | C5: Joint Account | D5: 300 | E5: Example - delete | F5: =IF(C5="","",IFERROR(INDEX(Settings!$C$8:$C$19,MATCH(C5,Settings!$B$8:$B$19,0)),"?")) -> Joint | G5: =IF(A5="","",DATE(YEAR(A5),MONTH(A5),1)) -> 46235
A6: 46295 | B6: Emergency fund | C6: Joint Account | D6: 300 | E6: Example - delete | F6: =IF(C6="","",IFERROR(INDEX(Settings!$C$8:$C$19,MATCH(C6,Settings!$B$8:$B$19,0)),"?")) -> Joint | G6: =IF(A6="","",DATE(YEAR(A6),MONTH(A6),1)) -> 46266
A7: 46297 | B7: Holiday 2027 | C7: Me - Current | D7: 150 | E7: Example - delete | F7: =IF(C7="","",IFERROR(INDEX(Settings!$C$8:$C$19,MATCH(C7,Settings!$B$8:$B$19,0)),"?")) -> Me | G7: =IF(A7="","",DATE(YEAR(A7),MONTH(A7),1)) -> 46296
A8: 46297 | B8: New car | C8: Me - Current | D8: 200 | E8: Example - delete | F8: =IF(C8="","",IFERROR(INDEX(Settings!$C$8:$C$19,MATCH(C8,Settings!$B$8:$B$19,0)),"?")) -> Me | G8: =IF(A8="","",DATE(YEAR(A8),MONTH(A8),1)) -> 46296
A9: 46298 | B9: Holiday 2027 | C9: Partner - Current | D9: 150 | E9: Example - delete | F9: =IF(C9="","",IFERROR(INDEX(Settings!$C$8:$C$19,MATCH(C9,Settings!$B$8:$B$19,0)),"?")) -> Partner | G9: =IF(A9="","",DATE(YEAR(A9),MONTH(A9),1)) -> 46296
F10: =IF(C10="","",IFERROR(INDEX(Settings!$C$8:$C$19,MATCH(C10,Settings!$B$8:$B$19,0)),"?")) | G10: =IF(A10="","",DATE(YEAR(A10),MONTH(A10),1))
F11: =IF(C11="","",IFERROR(INDEX(Settings!$C$8:$C$19,MATCH(C11,Settings!$B$8:$B$19,0)),"?")) | G11: =IF(A11="","",DATE(YEAR(A11),MONTH(A11),1))
F12: =IF(C12="","",IFERROR(INDEX(Settings!$C$8:$C$19,MATCH(C12,Settings!$B$8:$B$19,0)),"?")) | G12: =IF(A12="","",DATE(YEAR(A12),MONTH(A12),1))
F13: =IF(C13="","",IFERROR(INDEX(Settings!$C$8:$C$19,MATCH(C13,Settings!$B$8:$B$19,0)),"?")) | G13: =IF(A13="","",DATE(YEAR(A13),MONTH(A13),1))
